Workbook

Sheet tips
A1: sex | B1: smoker | C1: day | D1: time | E1: size | F1: total_bill | G1: tip
A2: Female | B2: No | C2: Sun | D2: Dinner | E2: 2 | F2: 16.99 | G2: 1.01
A3: Male | B3: No | C3: Sun | D3: Dinner | E3: 3 | F3: 10.34 | G3: 1.66 | J3: sex | K3: Gender of the customer
A4: Male | B4: No | C4: Sun | D4: Dinner | E4: 3 | F4: 21.01 | G4: 3.5 | J4: smoker | K4: Indicates if the customer is a smoker or not
A5: Male | B5: No | C5: Sun | D5: Dinner | E5: 2 | F5: 23.68 | G5: 3.31 | J5: day | K5: Day of the restaurant visit
A6: Female | B6: No | C6: Sun | D6: Dinner | E6: 4 | F6: 24.59 | G6: 3.61 | J6: time | K6: Indicates whether the tip was for lunch or dinner
A7: Male | B7: No | C7: Sun | D7: Dinner | E7: 4 | F7: 25.29 | G7: 4.71 | J7: size | K7: Number of members dining
A8: Male | B8: No | C8: Sun | D8: Dinner | E8: 2 | F8: 8.77 | G8: 2 | J8: total bill | K8: Bill amount in USD
A9: Male | B9: No | C9: Sun | D9: Dinner | E9: 4 | F9: 26.88 | G9: 3.12 | J9: tip | K9: Tip amount in USD
A10: Male | B10: No | C10: Sun | D10: Dinner | E10: 2 | F10: 15.04 | G10: 1.96
A11: Male | B11: No | C11: Sun | D11: Dinner | E11: 2 | F11: 14.78 | G11: 3.23
A12: Male | B12: No | C12: Sun | D12: Dinner | E12: 2 | F12: 10.27 | G12: 1.71
A13: Female | B13: No | C13: Sun | D13: Dinner | E13: 4 | F13: 35.26 | G13: 5
A14: Male | B14: No | C14: Sun | D14: Dinner | E14: 2 | F14: 15.42 | G14: 1.57
A15: Male | B15: No | C15: Sun | D15: Dinner | E15: 4 | F15: 18.43 | G15: 3
A16: Female | B16: No | C16: Sun | D16: Dinner | E16: 2 | F16: 14.83 | G16: 3.02
A17: Male | B17: No | C17: Sun | D17: Dinner | E17: 2 | F17: 21.58 | G17: 3.92
A18: Female | B18: No | C18: Sun | D18: Dinner | E18: 3 | F18: 10.33 | G18: 1.67
A19: Male | B19: No | C19: Sun | D19: Dinner | E19: 3 | F19: 16.29 | G19: 3.71
A20: Female | B20: No | C20: Sun | D20: Dinner | E20: 3 | F20: 16.97 | G20: 3.5
A21: Male | B21: No | C21: Sat | D21: Dinner | E21: 3 | F21: 20.65 | G21: 3.35
... A245: Female | B245: No | C245: Thur | D245: Dinner | E245: 2 | F245: 18.78 | G245: 3

Sheet CORRELATION IN %
A1: sex | B1: smoker | C1: Sun | D1: Fri | E1: Sat | F1: Thur | G1: time | H1: size | I1: total_bill | J1: tip | L1: CORRELATION
A2: =IF(tips!A2="Female",1,IF(tips!A2="Male",0,"")) -> 1 | B2: =IF(tips!B2="Yes",1,IF(tips!B2="No",0,"")) -> 0 | C2: =IF(tips!$C2="Sun",1,0) -> 1 | D2: =IF(tips!$C2="Fri",1,0) -> 0 | E2: =IF(tips!$C2="Sat",1,0) -> 0 | F2: =IF(tips!$C2="Thur",1,0) -> 0 | G2: =IF(tips!D2="Dinner",1,IF(tips!D2="Lunch",0,"")) -> 1 | H2: 2 | I2: 16.99 | J2: 1.01 | M2: sex | N2: smoker | O2: Sun | P2: Fri | Q2: Sat | R2: Thur | S2: time | T2: size | U2: total_bill | V2: tip
A3: =IF(tips!A3="Female",1,IF(tips!A3="Male",0,"")) -> 0 | B3: =IF(tips!B3="Yes",1,IF(tips!B3="No",0,"")) -> 0 | C3: =IF(tips!$C3="Sun",1,0) -> 1 | D3: =IF(tips!$C3="Fri",1,0) -> 0 | E3: =IF(tips!$C3="Sat",1,0) -> 0 | F3: =IF(tips!$C3="Thur",1,0) -> 0 | G3: =IF(tips!D3="Dinner",1,IF(tips!D3="Lunch",0,"")) -> 1 | H3: 3 | I3: 10.34 | J3: 1.66 | L3: sex | M3: 1
A4: =IF(tips!A4="Female",1,IF(tips!A4="Male",0,"")) -> 0 | B4: =IF(tips!B4="Yes",1,IF(tips!B4="No",0,"")) -> 0 | C4: =IF(tips!$C4="Sun",1,0) -> 1 | D4: =IF(tips!$C4="Fri",1,0) -> 0 | E4: =IF(tips!$C4="Sat",1,0) -> 0 | F4: =IF(tips!$C4="Thur",1,0) -> 0 | G4: =IF(tips!D4="Dinner",1,IF(tips!D4="Lunch",0,"")) -> 1 | H4: 3 | I4: 21.01 | J4: 3.5 | L4: smoker | M4: -0.0028159517 | N4: 1
A5: =IF(tips!A5="Female",1,IF(tips!A5="Male",0,"")) -> 0 | B5: =IF(tips!B5="Yes",1,IF(tips!B5="No",0,"")) -> 0 | C5: =IF(tips!$C5="Sun",1,0) -> 1 | D5: =IF(tips!$C5="Fri",1,0) -> 0 | E5: =IF(tips!$C5="Sat",1,0) -> 0 | F5: =IF(tips!$C5="Thur",1,0) -> 0 | G5: =IF(tips!D5="Dinner",1,IF(tips!D5="Lunch",0,"")) -> 1 | H5: 2 | I5: 23.68 | J5: 3.31 | L5: Sun | M5: -0.16810556 | N5: -0.18162356 | O5: 1
A6: =IF(tips!A6="Female",1,IF(tips!A6="Male",0,"")) -> 1 | B6: =IF(tips!B6="Yes",1,IF(tips!B6="No",0,"")) -> 0 | C6: =IF(tips!$C6="Sun",1,0) -> 1 | D6: =IF(tips!$C6="Fri",1,0) -> 0 | E6: =IF(tips!$C6="Sat",1,0) -> 0 | F6: =IF(tips!$C6="Thur",1,0) -> 0 | G6: =IF(tips!D6="Dinner",1,IF(tips!D6="Lunch",0,"")) -> 1 | H6: 4 | I6: 24.59 | J6: 3.61 | L6: Fri | M6: 0.071059528 | N6: 0.24431639 | O6: -0.19545091 | P6: 1
A7: =IF(tips!A7="Female",1,IF(tips!A7="Male",0,"")) -> 0 | B7: =IF(tips!B7="Yes",1,IF(tips!B7="No",0,"")) -> 0 | C7: =IF(tips!$C7="Sun",1,0) -> 1 | D7: =IF(tips!$C7="Fri",1,0) -> 0 | E7: =IF(tips!$C7="Sat",1,0) -> 0 | F7: =IF(tips!$C7="Thur",1,0) -> 0 | G7: =IF(tips!D7="Dinner",1,IF(tips!D7="Lunch",0,"")) -> 1 | H7: 4 | I7: 25.29 | J7: 4.71 | L7: Sat | M7: -0.053957098 | N7: 0.15574379 | O7: -0.50068197 | P7: -0.21631934 | Q7: 1
A8: =IF(tips!A8="Female",1,IF(tips!A8="Male",0,"")) -> 0 | B8: =IF(tips!B8="Yes",1,IF(tips!B8="No",0,"")) -> 0 | C8: =IF(tips!$C8="Sun",1,0) -> 1 | D8: =IF(tips!$C8="Fri",1,0) -> 0 | E8: =IF(tips!$C8="Sat",1,0) -> 0 | F8: =IF(tips!$C8="Thur",1,0) -> 0 | G8: =IF(tips!D8="Dinner",1,IF(tips!D8="Lunch",0,"")) -> 1 | H8: 2 | I8: 8.77 | J8: 2 | L8: Thur | M8: 0.19444477 | N8: -0.12853371 | O8: -0.39256566 | P8: -0.16960775 | Q8: -0.43448016 | R8: 1
A9: =IF(tips!A9="Female",1,IF(tips!A9="Male",0,"")) -> 0 | B9: =IF(tips!B9="Yes",1,IF(tips!B9="No",0,"")) -> 0 | C9: =IF(tips!$C9="Sun",1,0) -> 1 | D9: =IF(tips!$C9="Fri",1,0) -> 0 | E9: =IF(tips!$C9="Sat",1,0) -> 0 | F9: =IF(tips!$C9="Thur",1,0) -> 0 | G9: =IF(tips!D9="Dinner",1,IF(tips!D9="Lunch",0,"")) -> 1 | H9: 4 | I9: 26.88 | J9: 3.12 | L9: time | M9: -0.2052313 | N9: 0.054921104 | O9: 0.41807123 | P9: -0.058158672 | Q9: 0.46270897 | R9: -0.91799577 | S9: 1
A10: =IF(tips!A10="Female",1,IF(tips!A10="Male",0,"")) -> 0 | B10: =IF(tips!B10="Yes",1,IF(tips!B10="No",0,"")) -> 0 | C10: =IF(tips!$C10="Sun",1,0) -> 1 | D10: =IF(tips!$C10="Fri",1,0) -> 0 | E10: =IF(tips!$C10="Sat",1,0) -> 0 | F10: =IF(tips!$C10="Thur",1,0) -> 0 | G10: =IF(tips!D10="Dinner",1,IF(tips!D10="Lunch",0,"")) -> 1 | H10: 2 | I10: 15.04 | J10: 1.96 | L10: size | M10: -0.086194815 | N10: -0.13317825 | O10: 0.19305354 | P10: -0.14218436 | Q10: -0.041120801 | R10: -0.072598187 | S10: 0.10341091 | T10: 1
A11: =IF(tips!A11="Female",1,IF(tips!A11="Male",0,"")) -> 0 | B11: =IF(tips!B11="Yes",1,IF(tips!B11="No",0,"")) -> 0 | C11: =IF(tips!$C11="Sun",1,0) -> 1 | D11: =IF(tips!$C11="Fri",1,0) -> 0 | E11: =IF(tips!$C11="Sat",1,0) -> 0 | F11: =IF(tips!$C11="Thur",1,0) -> 0 | G11: =IF(tips!D11="Dinner",1,IF(tips!D11="Lunch",0,"")) -> 1 | H11: 2 | I11: 14.78 | J11: 3.23 | L11: total_bill | M11: -0.14487734 | N11: 0.085721257 | O11: 0.12295257 | P11: -0.08616787 | Q11: 0.054919255 | R11: -0.13817356 | S11: 0.18311761 | T11: 0.59831513 | U11: 1
A12: =IF(tips!A12="Female",1,IF(tips!A12="Male",0,"")) -> 0 | B12: =IF(tips!B12="Yes",1,IF(tips!B12="No",0,"")) -> 0 | C12: =IF(tips!$C12="Sun",1,0) -> 1 | D12: =IF(tips!$C12="Fri",1,0) -> 0 | E12: =IF(tips!$C12="Sat",1,0) -> 0 | F12: =IF(tips!$C12="Thur",1,0) -> 0 | G12: =IF(tips!D12="Dinner",1,IF(tips!D12="Lunch",0,"")) -> 1 | H12: 2 | I12: 10.27 | J12: 1.71 | L12: tip | M12: -0.088862061 | N12: 0.0059285395 | O12: 0.12511398 | P12: -0.055463128 | Q12: -0.0027900344 | R12: -0.095879173 | S12: 0.12162906 | T12: 0.48929878 | U12: 0.67573411 | V12: 1
A13: =IF(tips!A13="Female",1,IF(tips!A13="Male",0,"")) -> 1 | B13: =IF(tips!B13="Yes",1,IF(tips!B13="No",0,"")) -> 0 | C13: =IF(tips!$C13="Sun",1,0) -> 1 | D13: =IF(tips!$C13="Fri",1,0) -> 0 | E13: =IF(tips!$C13="Sat",1,0) -> 0 | F13: =IF(tips!$C13="Thur",1,0) -> 0 | G13: =IF(tips!D13="Dinner",1,IF(tips!D13="Lunch",0,"")) -> 1 | H13: 4 | I13: 35.26 | J13: 5
A14: =IF(tips!A14="Female",1,IF(tips!A14="Male",0,"")) -> 0 | B14: =IF(tips!B14="Yes",1,IF(tips!B14="No",0,"")) -> 0 | C14: =IF(tips!$C14="Sun",1,0) -> 1 | D14: =IF(tips!$C14="Fri",1,0) -> 0 | E14: =IF(tips!$C14="Sat",1,0) -> 0 | F14: =IF(tips!$C14="Thur",1,0) -> 0 | G14: =IF(tips!D14="Dinner",1,IF(tips!D14="Lunch",0,"")) -> 1 | H14: 2 | I14: 15.42 | J14: 1.57 | L14: Above correlation matrix suggest that only "size" & "total_bill" has strong relationship with tips,so we will use them in prediction model
A15: =IF(tips!A15="Female",1,IF(tips!A15="Male",0,"")) -> 0 | B15: =IF(tips!B15="Yes",1,IF(tips!B15="No",0,"")) -> 0 | C15: =IF(tips!$C15="Sun",1,0) -> 1 | D15: =IF(tips!$C15="Fri",1,0) -> 0 | E15: =IF(tips!$C15="Sat",1,0) -> 0 | F15: =IF(tips!$C15="Thur",1,0) -> 0 | G15: =IF(tips!D15="Dinner",1,IF(tips!D15="Lunch",0,"")) -> 1 | H15: 4 | I15: 18.43 | J15: 3
A16: =IF(tips!A16="Female",1,IF(tips!A16="Male",0,"")) -> 1 | B16: =IF(tips!B16="Yes",1,IF(tips!B16="No",0,"")) -> 0 | C16: =IF(tips!$C16="Sun",1,0) -> 1 | D16: =IF(tips!$C16="Fri",1,0) -> 0 | E16: =IF(tips!$C16="Sat",1,0) -> 0 | F16: =IF(tips!$C16="Thur",1,0) -> 0 | G16: =IF(tips!D16="Dinner",1,IF(tips!D16="Lunch",0,"")) -> 1 | H16: 2 | I16: 14.83 | J16: 3.02
A17: =IF(tips!A17="Female",1,IF(tips!A17="Male",0,"")) -> 0 | B17: =IF(tips!B17="Yes",1,IF(tips!B17="No",0,"")) -> 0 | C17: =IF(tips!$C17="Sun",1,0) -> 1 | D17: =IF(tips!$C17="Fri",1,0) -> 0 | E17: =IF(tips!$C17="Sat",1,0) -> 0 | F17: =IF(tips!$C17="Thur",1,0) -> 0 | G17: =IF(tips!D17="Dinner",1,IF(tips!D17="Lunch",0,"")) -> 1 | H17: 2 | I17: 21.58 | J17: 3.92
A18: =IF(tips!A18="Female",1,IF(tips!A18="Male",0,"")) -> 1 | B18: =IF(tips!B18="Yes",1,IF(tips!B18="No",0,"")) -> 0 | C18: =IF(tips!$C18="Sun",1,0) -> 1 | D18: =IF(tips!$C18="Fri",1,0) -> 0 | E18: =IF(tips!$C18="Sat",1,0) -> 0 | F18: =IF(tips!$C18="Thur",1,0) -> 0 | G18: =IF(tips!D18="Dinner",1,IF(tips!D18="Lunch",0,"")) -> 1 | H18: 3 | I18: 10.33 | J18: 1.67
A19: =IF(tips!A19="Female",1,IF(tips!A19="Male",0,"")) -> 0 | B19: =IF(tips!B19="Yes",1,IF(tips!B19="No",0,"")) -> 0 | C19: =IF(tips!$C19="Sun",1,0) -> 1 | D19: =IF(tips!$C19="Fri",1,0) -> 0 | E19: =IF(tips!$C19="Sat",1,0) -> 0 | F19: =IF(tips!$C19="Thur",1,0) -> 0 | G19: =IF(tips!D19="Dinner",1,IF(tips!D19="Lunch",0,"")) -> 1 | H19: 3 | I19: 16.29 | J19: 3.71
A20: =IF(tips!A20="Female",1,IF(tips!A20="Male",0,"")) -> 1 | B20: =IF(tips!B20="Yes",1,IF(tips!B20="No",0,"")) -> 0 | C20: =IF(tips!$C20="Sun",1,0) -> 1 | D20: =IF(tips!$C20="Fri",1,0) -> 0 | E20: =IF(tips!$C20="Sat",1,0) -> 0 | F20: =IF(tips!$C20="Thur",1,0) -> 0 | G20: =IF(tips!D20="Dinner",1,IF(tips!D20="Lunch",0,"")) -> 1 | H20: 3 | I20: 16.97 | J20: 3.5
A21: =IF(tips!A21="Female",1,IF(tips!A21="Male",0,"")) -> 0 | B21: =IF(tips!B21="Yes",1,IF(tips!B21="No",0,"")) -> 0 | C21: =IF(tips!$C21="Sun",1,0) -> 0 | D21: =IF(tips!$C21="Fri",1,0) -> 0 | E21: =IF(tips!$C21="Sat",1,0) -> 1 | F21: =IF(tips!$C21="Thur",1,0) -> 0 | G21: =IF(tips!D21="Dinner",1,IF(tips!D21="Lunch",0,"")) -> 1 | H21: 3 | I21: 20.65 | J21: 3.35
A22: =IF(tips!A22="Female",1,IF(tips!A22="Male",0,"")) -> 0 | B22: =IF(tips!B22="Yes",1,IF(tips!B22="No",0,"")) -> 0 | C22: =IF(tips!$C22="Sun",1,0) -> 0 | D22: =IF(tips!$C22="Fri",1,0) -> 0 | E22: =IF(tips!$C22="Sat",1,0) -> 1 | F22: =IF(tips!$C22="Thur",1,0) -> 0 | G22: =IF(tips!D22="Dinner",1,IF(tips!D22="Lunch",0,"")) -> 1 | H22: 2 | I22: 17.92 | J22: 4.08
A23: =IF(tips!A23="Female",1,IF(tips!A23="Male",0,"")) -> 1 | B23: =IF(tips!B23="Yes",1,IF(tips!B23="No",0,"")) -> 0 | C23: =IF(tips!$C23="Sun",1,0) -> 0 | D23: =IF(tips!$C23="Fri",1,0) -> 0 | E23: =IF(tips!$C23="Sat",1,0) -> 1 | F23: =IF(tips!$C23="Thur",1,0) -> 0 | G23: =IF(tips!D23="Dinner",1,IF(tips!D23="Lunch",0,"")) -> 1 | H23: 2 | I23: 20.29 | J23: 2.75
A24: =IF(tips!A24="Female",1,IF(tips!A24="Male",0,"")) -> 1 | B24: =IF(tips!B24="Yes",1,IF(tips!B24="No",0,"")) -> 0 | C24: =IF(tips!$C24="Sun",1,0) -> 0 | D24: =IF(tips!$C24="Fri",1,0) -> 0 | E24: =IF(tips!$C24="Sat",1,0) -> 1 | F24: =IF(tips!$C24="Thur",1,0) -> 0 | G24: =IF(tips!D24="Dinner",1,IF(tips!D24="Lunch",0,"")) -> 1 | H24: 2 | I24: 15.77 | J24: 2.23
A25: =IF(tips!A25="Female",1,IF(tips!A25="Male",0,"")) -> 0 | B25: =IF(tips!B25="Yes",1,IF(tips!B25="No",0,"")) -> 0 | C25: =IF(tips!$C25="Sun",1,0) -> 0 | D25: =IF(tips!$C25="Fri",1,0) -> 0 | E25: =IF(tips!$C25="Sat",1,0) -> 1 | F25: =IF(tips!$C25="Thur",1,0) -> 0 | G25: =IF(tips!D25="Dinner",1,IF(tips!D25="Lunch",0,"")) -> 1 | H25: 4 | I25: 39.42 | J25: 7.58
A26: =IF(tips!A26="Female",1,IF(tips!A26="Male",0,"")) -> 0 | B26: =IF(tips!B26="Yes",1,IF(tips!B26="No",0,"")) -> 0 | C26: =IF(tips!$C26="Sun",1,0) -> 0 | D26: =IF(tips!$C26="Fri",1,0) -> 0 | E26: =IF(tips!$C26="Sat",1,0) -> 1 | F26: =IF(tips!$C26="Thur",1,0) -> 0 | G26: =IF(tips!D26="Dinner",1,IF(tips!D26="Lunch",0,"")) -> 1 | H26: 2 | I26: 19.82 | J26: 3.18 | L26: CORRELATION
A27: =IF(tips!A27="Female",1,IF(tips!A27="Male",0,"")) -> 0 | B27: =IF(tips!B27="Yes",1,IF(tips!B27="No",0,"")) -> 0 | C27: =IF(tips!$C27="Sun",1,0) -> 0 | D27: =IF(tips!$C27="Fri",1,0) -> 0 | E27: =IF(tips!$C27="Sat",1,0) -> 1 | F27: =IF(tips!$C27="Thur",1,0) -> 0 | G27: =IF(tips!D27="Dinner",1,IF(tips!D27="Lunch",0,"")) -> 1 | H27: 4 | I27: 17.81 | J27: 2.34 | M27: sex | N27: smoker | O27: Sun | P27: Fri | Q27: Sat | R27: Thur | S27: time | T27: size | U27: total_bill | V27: tip
A28: =IF(tips!A28="Female",1,IF(tips!A28="Male",0,"")) -> 0 | B28: =IF(tips!B28="Yes",1,IF(tips!B28="No",0,"")) -> 0 | C28: =IF(tips!$C28="Sun",1,0) -> 0 | D28: =IF(tips!$C28="Fri",1,0) -> 0 | E28: =IF(tips!$C28="Sat",1,0) -> 1 | F28: =IF(tips!$C28="Thur",1,0) -> 0 | G28: =IF(tips!D28="Dinner",1,IF(tips!D28="Lunch",0,"")) -> 1 | H28: 2 | I28: 13.37 | J28: 2 | L28: sex | M28: 1
A29: =IF(tips!A29="Female",1,IF(tips!A29="Male",0,"")) -> 0 | B29: =IF(tips!B29="Yes",1,IF(tips!B29="No",0,"")) -> 0 | C29: =IF(tips!$C29="Sun",1,0) -> 0 | D29: =IF(tips!$C29="Fri",1,0) -> 0 | E29: =IF(tips!$C29="Sat",1,0) -> 1 | F29: =IF(tips!$C29="Thur",1,0) -> 0 | G29: =IF(tips!D29="Dinner",1,IF(tips!D29="Lunch",0,"")) -> 1 | H29: 2 | I29: 12.69 | J29: 2 | L29: smoker | M29: -0.0028159517 | N29: 1
A30: =IF(tips!A30="Female",1,IF(tips!A30="Male",0,"")) -> 0 | B30: =IF(tips!B30="Yes",1,IF(tips!B30="No",0,"")) -> 0 | C30: =IF(tips!$C30="Sun",1,0) -> 0 | D30: =IF(tips!$C30="Fri",1,0) -> 0 | E30: =IF(tips!$C30="Sat",1,0) -> 1 | F30: =IF(tips!$C30="Thur",1,0) -> 0 | G30: =IF(tips!D30="Dinner",1,IF(tips!D30="Lunch",0,"")) -> 1 | H30: 2 | I30: 21.7 | J30: 4.3 | L30: Sun | M30: -0.16810556 | N30: -0.18162356 | O30: 1
A31: =IF(tips!A31="Female",1,IF(tips!A31="Male",0,"")) -> 1 | B31: =IF(tips!B31="Yes",1,IF(tips!B31="No",0,"")) -> 0 | C31: =IF(tips!$C31="Sun",1,0) -> 0 | D31: =IF(tips!$C31="Fri",1,0) -> 0 | E31: =IF(tips!$C31="Sat",1,0) -> 1 | F31: =IF(tips!$C31="Thur",1,0) -> 0 | G31: =IF(tips!D31="Dinner",1,IF(tips!D31="Lunch",0,"")) -> 1 | H31: 2 | I31: 19.65 | J31: 3 | L31: Fri | M31: 0.071059528 | N31: 0.24431639 | O31: -0.19545091 | P31: 1
A32: =IF(tips!A32="Female",1,IF(tips!A32="Male",0,"")) -> 0 | B32: =IF(tips!B32="Yes",1,IF(tips!B32="No",0,"")) -> 0 | C32: =IF(tips!$C32="Sun",1,0) -> 0 | D32: =IF(tips!$C32="Fri",1,0) -> 0 | E32: =IF(tips!$C32="Sat",1,0) -> 1 | F32: =IF(tips!$C32="Thur",1,0) -> 0 | G32: =IF(tips!D32="Dinner",1,IF(tips!D32="Lunch",0,"")) -> 1 | H32: 2 | I32: 9.55 | J32: 1.45 | L32: Sat | M32: -0.053957098 | N32: 0.15574379 | O32: -0.50068197 | P32: -0.21631934 | Q32: 1
A33: =IF(tips!A33="Female",1,IF(tips!A33="Male",0,"")) -> 0 | B33: =IF(tips!B33="Yes",1,IF(tips!B33="No",0,"")) -> 0 | C33: =IF(tips!$C33="Sun",1,0) -> 0 | D33: =IF(tips!$C33="Fri",1,0) -> 0 | E33: =IF(tips!$C33="Sat",1,0) -> 1 | F33: =IF(tips!$C33="Thur",1,0) -> 0 | G33: =IF(tips!D33="Dinner",1,IF(tips!D33="Lunch",0,"")) -> 1 | H33: 4 | I33: 18.35 | J33: 2.5 | L33: Thur | M33: 0.19444477 | N33: -0.12853371 | O33: -0.39256566 | P33: -0.16960775 | Q33: -0.43448016 | R33: 1
A34: =IF(tips!A34="Female",1,IF(tips!A34="Male",0,"")) -> 1 | B34: =IF(tips!B34="Yes",1,IF(tips!B34="No",0,"")) -> 0 | C34: =IF(tips!$C34="Sun",1,0) -> 0 | D34: =IF(tips!$C34="Fri",1,0) -> 0 | E34: =IF(tips!$C34="Sat",1,0) -> 1 | F34: =IF(tips!$C34="Thur",1,0) -> 0 | G34: =IF(tips!D34="Dinner",1,IF(tips!D34="Lunch",0,"")) -> 1 | H34: 2 | I34: 15.06 | J34: 3 | L34: time | M34: -0.2052313 | N34: 0.054921104 | O34: 0.41807123 | P34: -0.058158672 | Q34: 0.46270897 | R34: -0.91799577 | S34: 1
A35: =IF(tips!A35="Female",1,IF(tips!A35="Male",0,"")) -> 1 | B35: =IF(tips!B35="Yes",1,IF(tips!B35="No",0,"")) -> 0 | C35: =IF(tips!$C35="Sun",1,0) -> 0 | D35: =IF(tips!$C35="Fri",1,0) -> 0 | E35: =IF(tips!$C35="Sat",1,0) -> 1 | F35: =IF(tips!$C35="Thur",1,0) -> 0 | G35: =IF(tips!D35="Dinner",1,IF(tips!D35="Lunch",0,"")) -> 1 | H35: 4 | I35: 20.69 | J35: 2.45 | L35: size | M35: -0.086194815 | N35: -0.13317825 | O35: 0.19305354 | P35: -0.14218436 | Q35: -0.041120801 | R35: -0.072598187 | S35: 0.10341091 | T35: 1
A36: =IF(tips!A36="Female",1,IF(tips!A36="Male",0,"")) -> 0 | B36: =IF(tips!B36="Yes",1,IF(tips!B36="No",0,"")) -> 0 | C36: =IF(tips!$C36="Sun",1,0) -> 0 | D36: =IF(tips!$C36="Fri",1,0) -> 0 | E36: =IF(tips!$C36="Sat",1,0) -> 1 | F36: =IF(tips!$C36="Thur",1,0) -> 0 | G36: =IF(tips!D36="Dinner",1,IF(tips!D36="Lunch",0,"")) -> 1 | H36: 2 | I36: 17.78 | J36: 3.27 | L36: total_bill | M36: -0.14487734 | N36: 0.085721257 | O36: 0.12295257 | P36: -0.08616787 | Q36: 0.054919255 | R36: -0.13817356 | S36: 0.18311761 | T36: 0.59831513 | U36: 1
A37: =IF(tips!A37="Female",1,IF(tips!A37="Male",0,"")) -> 0 | B37: =IF(tips!B37="Yes",1,IF(tips!B37="No",0,"")) -> 0 | C37: =IF(tips!$C37="Sun",1,0) -> 0 | D37: =IF(tips!$C37="Fri",1,0) -> 0 | E37: =IF(tips!$C37="Sat",1,0) -> 1 | F37: =IF(tips!$C37="Thur",1,0) -> 0 | G37: =IF(tips!D37="Dinner",1,IF(tips!D37="Lunch",0,"")) -> 1 | H37: 3 | I37: 24.06 | J37: 3.6 | L37: tip | M37: -0.088862061 | N37: 0.0059285395 | O37: 0.12511398 | P37: -0.055463128 | Q37: -0.0027900344 | R37: -0.095879173 | S37: 0.12162906 | T37: 0.48929878 | U37: 0.67573411 | V37: 1
A38: =IF(tips!A38="Female",1,IF(tips!A38="Male",0,"")) -> 0 | B38: =IF(tips!B38="Yes",1,IF(tips!B38="No",0,"")) -> 0 | C38: =IF(tips!$C38="Sun",1,0) -> 0 | D38: =IF(tips!$C38="Fri",1,0) -> 0 | E38: =IF(tips!$C38="Sat",1,0) -> 1 | F38: =IF(tips!$C38="Thur",1,0) -> 0 | G38: =IF(tips!D38="Dinner",1,IF(tips!D38="Lunch",0,"")) -> 1 | H38: 3 | I38: 16.31 | J38: 2
A39: =IF(tips!A39="Female",1,IF(tips!A39="Male",0,"")) -> 1 | B39: =IF(tips!B39="Yes",1,IF(tips!B39="No",0,"")) -> 0 | C39: =IF(tips!$C39="Sun",1,0) -> 0 | D39: =IF(tips!$C39="Fri",1,0) -> 0 | E39: =IF(tips!$C39="Sat",1,0) -> 1 | F39: =IF(tips!$C39="Thur",1,0) -> 0 | G39: =IF(tips!D39="Dinner",1,IF(tips!D39="Lunch",0,"")) -> 1 | H39: 3 | I39: 16.93 | J39: 3.07
A40: =IF(tips!A40="Female",1,IF(tips!A40="Male",0,"")) -> 0 | B40: =IF(tips!B40="Yes",1,IF(tips!B40="No",0,"")) -> 0 | C40: =IF(tips!$C40="Sun",1,0) -> 0 | D40: =IF(tips!$C40="Fri",1,0) -> 0 | E40: =IF(tips!$C40="Sat",1,0) -> 1 | F40: =IF(tips!$C40="Thur",1,0) -> 0 | G40: =IF(tips!D40="Dinner",1,IF(tips!D40="Lunch",0,"")) -> 1 | H40: 3 | I40: 18.69 | J40: 2.31
...

Sheet Linear Regression -prediction
A1: size | B1: total_bill | C1: tip | D1: Predicted_Tip | E1: Squared_error | F1: RMSE | H1: SUMMARY OUTPUT
A2: 2 | B2: 16.99 | C2: 1.01 | D2: =SUM(PRODUCT(A2,$I$17),PRODUCT(B2,$I$18),$I$16) -> 2.6293399 | E2: =POWER((C2-D2),2) -> 2.6222618 | F2: =SQRT(SUM(E2:E245)/COUNT(E2:E245)) -> 1.0072561 | H2: Regression Statistics
A3: 3 | B3: 10.34 | C3: 1.66 | D3: =SUM(PRODUCT(A3,$I$17),PRODUCT(B3,$I$18),$I$16) -> 2.205394 | E3: =POWER((C3-D3),2) -> 0.29745464 | H3: Multiple R | I3: 0.68400973
A4: 3 | B4: 21.01 | C4: 3.5 | D4: =SUM(PRODUCT(A4,$I$17),PRODUCT(B4,$I$18),$I$16) -> 3.1946453 | E4: =POWER((C4-D4),2) -> 0.093241474 | H4: R Square | I4: 0.46786931
A5: 2 | B5: 23.68 | C5: 3.31 | D5: =SUM(PRODUCT(A5,$I$17),PRODUCT(B5,$I$18),$I$16) -> 3.2495921 | E5: =POWER((C5-D5),2) -> 0.0036491089 | H5: Adjusted R Square | I5: 0.46345329
A6: 4 | B6: 24.59 | C6: 3.61 | D6: =SUM(PRODUCT(A6,$I$17),PRODUCT(B6,$I$18),$I$16) -> 3.7191569 | E6: =POWER((C6-D6),2) -> 0.011915223 | H6: Standard Error | I6: 1.013506
A7: 4 | B7: 25.29 | C7: 4.71 | D7: =SUM(PRODUCT(A7,$I$17),PRODUCT(B7,$I$18),$I$16) -> 3.7840562 | E7: =POWER((C7-D7),2) -> 0.85737191 | H7: Observations | I7: 244
A8: 2 | B8: 8.77 | C8: 2 | D8: =SUM(PRODUCT(A8,$I$17),PRODUCT(B8,$I$18),$I$16) -> 1.8672363 | E8: =POWER((C8-D8),2) -> 0.017626202
A9: 4 | B9: 26.88 | C9: 3.12 | D9: =SUM(PRODUCT(A9,$I$17),PRODUCT(B9,$I$18),$I$16) -> 3.9314704 | E9: =POWER((C9-D9),2) -> 0.65848423 | H9: ANOVA
A10: 2 | B10: 15.04 | C10: 1.96 | D10: =SUM(PRODUCT(A10,$I$17),PRODUCT(B10,$I$18),$I$16) -> 2.4485489 | E10: =POWER((C10-D10),2) -> 0.23868004 | I10: df | J10: SS | K10: MS | L10: F | M10: Significance F
A11: 2 | B11: 14.78 | C11: 3.23 | D11: =SUM(PRODUCT(A11,$I$17),PRODUCT(B11,$I$18),$I$16) -> 2.4244434 | E11: =POWER((C11-D11),2) -> 0.64892136 | H11: Regression | I11: 2 | J11: 217.65864 | K11: 108.82932 | L11: 105.94813 | M11: 9.6650948e-34
A12: 2 | B12: 10.27 | C12: 1.71 | D12: =SUM(PRODUCT(A12,$I$17),PRODUCT(B12,$I$18),$I$16) -> 2.0063063 | E12: =POWER((C12-D12),2) -> 0.087797423 | H12: Residual | I12: 241 | J12: 247.55384 | K12: 1.0271943
A13: 4 | B13: 35.26 | C13: 5 | D13: =SUM(PRODUCT(A13,$I$17),PRODUCT(B13,$I$18),$I$16) -> 4.7084082 | E13: =POWER((C13-D13),2) -> 0.085025792 | H13: Total | I13: 243 | J13: 465.21248
A14: 2 | B14: 15.42 | C14: 1.57 | D14: =SUM(PRODUCT(A14,$I$17),PRODUCT(B14,$I$18),$I$16) -> 2.48378 | E14: =POWER((C14-D14),2) -> 0.83499386
A15: 4 | B15: 18.43 | C15: 3 | D15: =SUM(PRODUCT(A15,$I$17),PRODUCT(B15,$I$18),$I$16) -> 3.1480427 | E15: =POWER((C15-D15),2) -> 0.021916646 | I15: Coefficients | J15: Standard Error | K15: t Stat | L15: P-value | M15: Lower 95% | N15: Upper 95% | O15: Lower 95.0% | P15: Upper 95.0%
A16: 2 | B16: 14.83 | C16: 3.02 | D16: =SUM(PRODUCT(A16,$I$17),PRODUCT(B16,$I$18),$I$16) -> 2.4290791 | E16: =POWER((C16-D16),2) -> 0.34918749 | H16: Intercept | I16: 0.66894474 | J16: 0.19360933 | K16: 3.4551265 | L16: 0.00064980607 | M16: 0.2875622 | N16: 1.0503273 | O16: 0.2875622 | P16: 1.0503273
A17: 2 | B17: 21.58 | C17: 3.92 | D17: =SUM(PRODUCT(A17,$I$17),PRODUCT(B17,$I$18),$I$16) -> 3.0548941 | E17: =POWER((C17-D17),2) -> 0.74840815 | H17: size | I17: 0.19259779 | J17: 0.085314557 | K17: 2.2575021 | L17: 0.024872446 | M17: 0.024540385 | N17: 0.3606552 | O17: 0.024540385 | P17: 0.3606552
A18: 3 | B18: 10.33 | C18: 1.67 | D18: =SUM(PRODUCT(A18,$I$17),PRODUCT(B18,$I$18),$I$16) -> 2.2044669 | E18: =POWER((C18-D18),2) -> 0.28565486 | H18: total_bill | I18: 0.092713337 | J18: 0.0091146825 | K18: 10.171867 | L18: 1.880917e-20 | M18: 0.074758723 | N18: 0.11066795 | O18: 0.074758723 | P18: 0.11066795
A19: 3 | B19: 16.29 | C19: 3.71 | D19: =SUM(PRODUCT(A19,$I$17),PRODUCT(B19,$I$18),$I$16) -> 2.7570384 | E19: =POWER((C19-D19),2) -> 0.90813585
A20: 3 | B20: 16.97 | C20: 3.5 | D20: =SUM(PRODUCT(A20,$I$17),PRODUCT(B20,$I$18),$I$16) -> 2.8200835 | E20: =POWER((C20-D20),2) -> 0.46228651 | H20: Hence, Predicted_Tips (y)=0.193*size+0.093*total_bill+0.665 (x1y1+x2y2+….....xnyn+C)
A21: 3 | B21: 20.65 | C21: 3.35 | D21: =SUM(PRODUCT(A21,$I$17),PRODUCT(B21,$I$18),$I$16) -> 3.1612685 | E21: =POWER((C21-D21),2) -> 0.035619568 | H21: Observation | I21: Predicted tip | J21: Residuals | K21: Standard Residuals | L21: Percentile | M21: tip | N21: Squared_error | O21: RMSE
A22: 2 | B22: 17.92 | C22: 4.08 | D22: =SUM(PRODUCT(A22,$I$17),PRODUCT(B22,$I$18),$I$16) -> 2.7155633 | E22: =POWER((C22-D22),2) -> 1.8616874 | H22: 1 | I22: 2.6293399 | J22: -1.6193399 | K22: -1.6043766 | L22: 0.20491803 | M22: 1 | N22: 2.6222618 | O22: 1.0072561
A23: 2 | B23: 20.29 | C23: 2.75 | D23: =SUM(PRODUCT(A23,$I$17),PRODUCT(B23,$I$18),$I$16) -> 2.9352939 | E23: =POWER((C23-D23),2) -> 0.034333842 | H23: 2 | I23: 2.205394 | J23: -0.54539403 | K23: -0.54035439 | L23: 0.6147541 | M23: 1 | N23: 0.29745464
A24: 2 | B24: 15.77 | C24: 2.23 | D24: =SUM(PRODUCT(A24,$I$17),PRODUCT(B24,$I$18),$I$16) -> 2.5162297 | E24: =POWER((C24-D24),2) -> 0.081927413 | H24: 3 | I24: 3.1946453 | J24: 0.30535467 | K24: 0.30253308 | L24: 1.0245902 | M24: 1 | N24: 0.093241474
A25: 4 | B25: 39.42 | C25: 7.58 | D25: =SUM(PRODUCT(A25,$I$17),PRODUCT(B25,$I$18),$I$16) -> 5.0940957 | E25: =POWER((C25-D25),2) -> 6.1797204 | H25: 4 | I25: 3.2495921 | J25: 0.060407854 | K25: 0.059849664 | L25: 1.4344262 | M25: 1 | N25: 0.0036491089
A26: 2 | B26: 19.82 | C26: 3.18 | D26: =SUM(PRODUCT(A26,$I$17),PRODUCT(B26,$I$18),$I$16) -> 2.8917187 | E26: =POWER((C26-D26),2) -> 0.083106128 | H26: 5 | I26: 3.7191569 | J26: -0.10915687 | K26: -0.10814822 | L26: 1.8442623 | M26: 1.01 | N26: 0.011915223
A27: 4 | B27: 17.81 | C27: 2.34 | D27: =SUM(PRODUCT(A27,$I$17),PRODUCT(B27,$I$18),$I$16) -> 3.0905604 | E27: =POWER((C27-D27),2) -> 0.56334099 | H27: 6 | I27: 3.7840562 | J27: 0.92594379 | K27: 0.91738774 | L27: 2.2540984 | M27: 1.1 | N27: 0.85737191
A28: 2 | B28: 13.37 | C28: 2 | D28: =SUM(PRODUCT(A28,$I$17),PRODUCT(B28,$I$18),$I$16) -> 2.2937176 | E28: =POWER((C28-D28),2) -> 0.086270054 | H28: 7 | I28: 1.8672363 | J28: 0.13276371 | K28: 0.13153692 | L28: 2.6639344 | M28: 1.17 | N28: 0.017626202
A29: 2 | B29: 12.69 | C29: 2 | D29: =SUM(PRODUCT(A29,$I$17),PRODUCT(B29,$I$18),$I$16) -> 2.2306726 | E29: =POWER((C29-D29),2) -> 0.053209836 | H29: 8 | I29: 3.9314704 | J29: -0.81147041 | K29: -0.80397213 | L29: 3.0737705 | M29: 1.25 | N29: 0.65848423
A30: 2 | B30: 21.7 | C30: 4.3 | D30: =SUM(PRODUCT(A30,$I$17),PRODUCT(B30,$I$18),$I$16) -> 3.0660197 | E30: =POWER((C30-D30),2) -> 1.5227073 | H30: 9 | I30: 2.4485489 | J30: -0.48854892 | K30: -0.48403455 | L30: 3.4836066 | M30: 1.25 | N30: 0.23868004
A31: 2 | B31: 19.65 | C31: 3 | D31: =SUM(PRODUCT(A31,$I$17),PRODUCT(B31,$I$18),$I$16) -> 2.8759574 | E31: =POWER((C31-D31),2) -> 0.015386567 | H31: 10 | I31: 2.4244434 | J31: 0.80555655 | K31: 0.79811292 | L31: 3.8934426 | M31: 1.25 | N31: 0.64892136
A32: 2 | B32: 9.55 | C32: 1.45 | D32: =SUM(PRODUCT(A32,$I$17),PRODUCT(B32,$I$18),$I$16) -> 1.9395527 | E32: =POWER((C32-D32),2) -> 0.23966184 | H32: 11 | I32: 2.0063063 | J32: -0.2963063 | K32: -0.29356832 | L32: 4.3032787 | M32: 1.32 | N32: 0.087797423
A33: 4 | B33: 18.35 | C33: 2.5 | D33: =SUM(PRODUCT(A33,$I$17),PRODUCT(B33,$I$18),$I$16) -> 3.1406256 | E33: =POWER((C33-D33),2) -> 0.41040122 | H33: 12 | I33: 4.7084082 | J33: 0.29159182 | K33: 0.28889741 | L33: 4.7131148 | M33: 1.36 | N33: 0.085025792
A34: 2 | B34: 15.06 | C34: 3 | D34: =SUM(PRODUCT(A34,$I$17),PRODUCT(B34,$I$18),$I$16) -> 2.4504032 | E34: =POWER((C34-D34),2) -> 0.30205666 | H34: 13 | I34: 2.48378 | J34: -0.91377998 | K34: -0.90533633 | L34: 5.1229508 | M34: 1.44 | N34: 0.83499386
... A245: 2 | B245: 18.78 | C245: 3 | D245: =SUM(PRODUCT(A245,$I$17),PRODUCT(B245,$I$18),$I$16) -> 2.7952968 | E245: =POWER((C245-D245),2) -> 0.041903402 | H245: 224 | I245: 2.7282972 | J245: 0.27170275 | K245: 0.26919212 | L245: 91.598361 | M245: 5 | N245: 0.073822386
H246: 225 | I246: 2.2983533 | J246: -0.71835331 | K246: -0.71171547 | L246: 92.008197 | M246: 5 | N246: 0.51603148
H247: 226 | I247: 2.5625863 | J247: -0.06258632 | K247: -0.062008 | L247: 92.418033 | M247: 5 | N247: 0.0039170474
H248: 227 | I248: 1.9896179 | J248: 0.010382102 | K248: 0.010286167 | L248: 92.827869 | M248: 5.07 | N248: 0.00010778804
H249: 228 | I249: 3.3353237 | J249: -0.33532366 | K249: -0.33222514 | L249: 93.237705 | M249: 5.14 | N249: 0.11244195
H250: 229 | I250: 2.2853734 | J250: 0.43462656 | K250: 0.43061045 | L250: 93.647541 | M250: 5.15 | N250: 0.18890024
...

Sheet Parameters
A1: Parameters
A2: Sex | B2: Code | C2: Smoke | D2: Code | E2: TIME | F2: Code
A3: MALE | B3: 1 | C3: YES | D3: 1 | E3: DINNER | F3: 1
A4: FEMALE | B4: 0 | C4: NO | D4: 0 | E4: LUNCH | F4: 0
